Workbook

Sheet Episodes
A1: Id | B1: EraId | C1: EraDescription | D1: EpisodeFormatId | E1: EpisodeFormatDescription | F1: Doctor | G1: Actor | H1: Season | I1: SeasonFormatId | J1: SeasonFormatDescription | K1: Story | L1: StoryInSeason | M1: StoryTitle | N1: PartInStory | O1: PartTitle | P1: EpisodeInSeason | Q1: OriginalAirDate | R1: Runtime | S1: IsMissing | T1: WriterIds | U1: Writers | V1: WriterAliasId | W1: WriterAlias | X1: OvernightRatings | Y1: ConsolidatedRatings | Z1: ExtendedRatings | AA1: PopulationAdjustedOvernightRatings | AB1: PopulationAdjustedConsolidatedRatings | AC1: PopulationAdjustedExtendedRatings | AD1: Population | AE1: PopulationFactor | AF1: Note | AG1: WikiFormatId | AH1: WikiFormatDescription | AI1: WikiUrl
A3: 1 | B3: 1 | C3: =VLOOKUP(B3,Eras!$A$3:$B$999,2,0) -> Classic | D3: 1 | E3: =VLOOKUP(D3,EpisodeFormats!$A$3:$B$999,2,0) -> Series | F3: 1 | G3: =VLOOKUP(F3,Doctors!$A$3:$B$999,2,0) -> William Hartnell | H3: 1 | I3: 1 | J3: =VLOOKUP(I3,SeasonFormats!$A$3:$B$999,2,0) -> Season | K3: 1 | L3: 1 | M3: An Unearthly Child | N3: 1 | O3: An Unearthly Child | P3: 1 | Q3: 1963-11-23 | R3: -25 | T3: 21 | U3: {=_xlfn.TEXTJOIN(",",TRUE,_xlfn.XLOOKUP(_xlfn.FILTERXML("<t><s>" & SUBSTITUTE(T3,",","</s><s>") & "</s></t>", "//s"),Writers!$A$3:$A$999,Writers!$B$3:$B$999,""))} -> Anthony Coburn | W3: =IF(V3="","",_xlfn.XLOOKUP(V3,Writers!$A$3:$A$999,Writers!$B$3:$B$999,"")) | X3: 4.4 | AA3: =IF(ISBLANK(X3),"",ROUND(X3*AE3,2)) -> 5.6 | AB3: =IF(ISBLANK(Y3),"",ROUND(Y3*AE3,2)) | AC3: =IF(ISBLANK(Z3),"",ROUND(Z3*AE3,2)) | AD3: =VLOOKUP(YEAR(Q3),Populations!$A$3:$B$999,2,0) -> 53624900 | AE3: =(Calculations!B1/AD3) -> 1.273754 | AG3: 1 | AH3: =VLOOKUP(AG3,WikiFormats!$A$3:$B$999,2,0) -> Story | AI3: https://en.wikipedia.org/wiki/An_Unearthly_Child
A4: 2 | B4: 1 | C4: =VLOOKUP(B4,Eras!$A$3:$B$999,2,0) -> Classic | D4: 1 | E4: =VLOOKUP(D4,EpisodeFormats!$A$3:$B$999,2,0) -> Series | F4: 1 | G4: =VLOOKUP(F4,Doctors!$A$3:$B$999,2,0) -> William Hartnell | H4: 1 | I4: 1 | J4: =VLOOKUP(I4,SeasonFormats!$A$3:$B$999,2,0) -> Season | K4: 1 | L4: 1 | M4: An Unearthly Child | N4: 2 | O4: The Cave of Skulls | P4: 2 | Q4: 1963-11-30 | R4: -25 | T4: 21 | U4: {=_xlfn.TEXTJOIN(",",TRUE,_xlfn.XLOOKUP(_xlfn.FILTERXML("<t><s>" & SUBSTITUTE(T4,",","</s><s>") & "</s></t>", "//s"),Writers!$A$3:$A$999,Writers!$B$3:$B$999,""))} -> Anthony Coburn | W4: =IF(V4="","",_xlfn.XLOOKUP(V4,Writers!$A$3:$A$999,Writers!$B$3:$B$999,"")) | X4: 5.9 | AA4: =IF(ISBLANK(X4),"",ROUND(X4*AE4,2)) -> 7.52 | AB4: =IF(ISBLANK(Y4),"",ROUND(Y4*AE4,2)) | AC4: =IF(ISBLANK(Z4),"",ROUND(Z4*AE4,2)) | AD4: =VLOOKUP(YEAR(Q4),Populations!$A$3:$B$999,2,0) -> 53624900 | AE4: =(Calculations!B1/AD4) -> 1.273754 | AG4: 1 | AH4: =VLOOKUP(AG4,WikiFormats!$A$3:$B$999,2,0) -> Story | AI4: https://en.wikipedia.org/wiki/An_Unearthly_Child
A5: 3 | B5: 1 | C5: =VLOOKUP(B5,Eras!$A$3:$B$999,2,0) -> Classic | D5: 1 | E5: =VLOOKUP(D5,EpisodeFormats!$A$3:$B$999,2,0) -> Series | F5: 1 | G5: =VLOOKUP(F5,Doctors!$A$3:$B$999,2,0) -> William Hartnell | H5: 1 | I5: 1 | J5: =VLOOKUP(I5,SeasonFormats!$A$3:$B$999,2,0) -> Season | K5: 1 | L5: 1 | M5: An Unearthly Child | N5: 3 | O5: The Forest of Fear | P5: 3 | Q5: 1963-12-07 | R5: -25 | T5: 21 | U5: {=_xlfn.TEXTJOIN(",",TRUE,_xlfn.XLOOKUP(_xlfn.FILTERXML("<t><s>" & SUBSTITUTE(T5,",","</s><s>") & "</s></t>", "//s"),Writers!$A$3:$A$999,Writers!$B$3:$B$999,""))} -> Anthony Coburn | W5: =IF(V5="","",_xlfn.XLOOKUP(V5,Writers!$A$3:$A$999,Writers!$B$3:$B$999,"")) | X5: 6.9 | AA5: =IF(ISBLANK(X5),"",ROUND(X5*AE5,2)) -> 8.79 | AB5: =IF(ISBLANK(Y5),"",ROUND(Y5*AE5,2)) | AC5: =IF(ISBLANK(Z5),"",ROUND(Z5*AE5,2)) | AD5: =VLOOKUP(YEAR(Q5),Populations!$A$3:$B$999,2,0) -> 53624900 | AE5: =(Calculations!B1/AD5) -> 1.273754 | AG5: 1 | AH5: =VLOOKUP(AG5,WikiFormats!$A$3:$B$999,2,0) -> Story | AI5: https://en.wikipedia.org/wiki/An_Unearthly_Child
A6: 4 | B6: 1 | C6: =VLOOKUP(B6,Eras!$A$3:$B$999,2,0) -> Classic | D6: 1 | E6: =VLOOKUP(D6,EpisodeFormats!$A$3:$B$999,2,0) -> Series | F6: 1 | G6: =VLOOKUP(F6,Doctors!$A$3:$B$999,2,0) -> William Hartnell | H6: 1 | I6: 1 | J6: =VLOOKUP(I6,SeasonFormats!$A$3:$B$999,2,0) -> Season | K6: 1 | L6: 1 | M6: An Unearthly Child | N6: 4 | O6: The Firemaker | P6: 4 | Q6: 1963-12-14 | R6: -25 | T6: 21 | U6: {=_xlfn.TEXTJOIN(",",TRUE,_xlfn.XLOOKUP(_xlfn.FILTERXML("<t><s>" & SUBSTITUTE(T6,",","</s><s>") & "</s></t>", "//s"),Writers!$A$3:$A$999,Writers!$B$3:$B$999,""))} -> Anthony Coburn | W6: =IF(V6="","",_xlfn.XLOOKUP(V6,Writers!$A$3:$A$999,Writers!$B$3:$B$999,"")) | X6: 6.4 | AA6: =IF(ISBLANK(X6),"",ROUND(X6*AE6,2)) -> 8.15 | AB6: =IF(ISBLANK(Y6),"",ROUND(Y6*AE6,2)) | AC6: =IF(ISBLANK(Z6),"",ROUND(Z6*AE6,2)) | AD6: =VLOOKUP(YEAR(Q6),Populations!$A$3:$B$999,2,0) -> 53624900 | AE6: =(Calculations!B1/AD6) -> 1.273754 | AG6: 1 | AH6: =VLOOKUP(AG6,WikiFormats!$A$3:$B$999,2,0) -> Story | AI6: https://en.wikipedia.org/wiki/An_Unearthly_Child
A7: 5 | B7: 1 | C7: =VLOOKUP(B7,Eras!$A$3:$B$999,2,0) -> Classic | D7: 1 | E7: =VLOOKUP(D7,EpisodeFormats!$A$3:$B$999,2,0) -> Series | F7: 1 | G7: =VLOOKUP(F7,Doctors!$A$3:$B$999,2,0) -> William Hartnell | H7: 1 | I7: 1 | J7: =VLOOKUP(I7,SeasonFormats!$A$3:$B$999,2,0) -> Season | K7: 2 | L7: 2 | M7: The Daleks | N7: 1 | O7: The Dead Planet | P7: 5 | Q7: 1963-12-21 | R7: 24 | T7: 81 | U7: {=_xlfn.TEXTJOIN(",",TRUE,_xlfn.XLOOKUP(_xlfn.FILTERXML("<t><s>" & SUBSTITUTE(T7,",","</s><s>") & "</s></t>", "//s"),Writers!$A$3:$A$999,Writers!$B$3:$B$999,""))} -> Terry Nation | W7: =IF(V7="","",_xlfn.XLOOKUP(V7,Writers!$A$3:$A$999,Writers!$B$3:$B$999,"")) | X7: 6.9 | AA7: =IF(ISBLANK(X7),"",ROUND(X7*AE7,2)) -> 8.79 | AB7: =IF(ISBLANK(Y7),"",ROUND(Y7*AE7,2)) | AC7: =IF(ISBLANK(Z7),"",ROUND(Z7*AE7,2)) | AD7: =VLOOKUP(YEAR(Q7),Populations!$A$3:$B$999,2,0) -> 53624900 | AE7: =(Calculations!B1/AD7) -> 1.273754 | AG7: 1 | AH7: =VLOOKUP(AG7,WikiFormats!$A$3:$B$999,2,0) -> Story | AI7: https://en.wikipedia.org/wiki/The_Daleks
A8: 6 | B8: 1 | C8: =VLOOKUP(B8,Eras!$A$3:$B$999,2,0) -> Classic | D8: 1 | E8: =VLOOKUP(D8,EpisodeFormats!$A$3:$B$999,2,0) -> Series | F8: 1 | G8: =VLOOKUP(F8,Doctors!$A$3:$B$999,2,0) -> William Hartnell | H8: 1 | I8: 1 | J8: =VLOOKUP(I8,SeasonFormats!$A$3:$B$999,2,0) -> Season | K8: 2 | L8: 2 | M8: The Daleks | N8: 2 | O8: The Survivors | P8: 6 | Q8: 1963-12-28 | R8: 24 | T8: 81 | U8: {=_xlfn.TEXTJOIN(",",TRUE,_xlfn.XLOOKUP(_xlfn.FILTERXML("<t><s>" & SUBSTITUTE(T8,",","</s><s>") & "</s></t>", "//s"),Writers!$A$3:$A$999,Writers!$B$3:$B$999,""))} -> Terry Nation | W8: =IF(V8="","",_xlfn.XLOOKUP(V8,Writers!$A$3:$A$999,Writers!$B$3:$B$999,"")) | X8: 6.4 | AA8: =IF(ISBLANK(X8),"",ROUND(X8*AE8,2)) -> 8.15 | AB8: =IF(ISBLANK(Y8),"",ROUND(Y8*AE8,2)) | AC8: =IF(ISBLANK(Z8),"",ROUND(Z8*AE8,2)) | AD8: =VLOOKUP(YEAR(Q8),Populations!$A$3:$B$999,2,0) -> 53624900 | AE8: =(Calculations!B1/AD8) -> 1.273754 | AG8: 1 | AH8: =VLOOKUP(AG8,WikiFormats!$A$3:$B$999,2,0) -> Story | AI8: https://en.wikipedia.org/wiki/The_Daleks
A9: 7 | B9: 1 | C9: =VLOOKUP(B9,Eras!$A$3:$B$999,2,0) -> Classic | D9: 1 | E9: =VLOOKUP(D9,EpisodeFormats!$A$3:$B$999,2,0) -> Series | F9: 1 | G9: =VLOOKUP(F9,Doctors!$A$3:$B$999,2,0) -> William Hartnell | H9: 1 | I9: 1 | J9: =VLOOKUP(I9,SeasonFormats!$A$3:$B$999,2,0) -> Season | K9: 2 | L9: 2 | M9: The Daleks | N9: 3 | O9: The Escape | P9: 7 | Q9: 1964-01-04 | R9: 25 | T9: 81 | U9: {=_xlfn.TEXTJOIN(",",TRUE,_xlfn.XLOOKUP(_xlfn.FILTERXML("<t><s>" & SUBSTITUTE(T9,",","</s><s>") & "</s></t>", "//s"),Writers!$A$3:$A$999,Writers!$B$3:$B$999,""))} -> Terry Nation | W9: =IF(V9="","",_xlfn.XLOOKUP(V9,Writers!$A$3:$A$999,Writers!$B$3:$B$999,"")) | X9: 8.9 | AA9: =IF(ISBLANK(X9),"",ROUND(X9*AE9,2)) -> 11.26 | AB9: =IF(ISBLANK(Y9),"",ROUND(Y9*AE9,2)) | AC9: =IF(ISBLANK(Z9),"",ROUND(Z9*AE9,2)) | AD9: =VLOOKUP(YEAR(Q9),Populations!$A$3:$B$999,2,0) -> 53990800 | AE9: =(Calculations!B1/AD9) -> 1.2651217 | AG9: 1 | AH9: =VLOOKUP(AG9,WikiFormats!$A$3:$B$999,2,0) -> Story | AI9: https://en.wikipedia.org/wiki/The_Daleks
A10: 8 | B10: 1 | C10: =VLOOKUP(B10,Eras!$A$3:$B$999,2,0) -> Classic | D10: 1 | E10: =VLOOKUP(D10,EpisodeFormats!$A$3:$B$999,2,0) -> Series | F10: 1 | G10: =VLOOKUP(F10,Doctors!$A$3:$B$999,2,0) -> William Hartnell | H10: 1 | I10: 1 | J10: =VLOOKUP(I10,SeasonFormats!$A$3:$B$999,2,0) -> Season | K10: 2 | L10: 2 | M10: The Daleks | N10: 4 | O10: The Ambush | P10: 8 | Q10: 1964-01-11 | R10: 24 | T10: 81 | U10: {=_xlfn.TEXTJOIN(",",TRUE,_xlfn.XLOOKUP(_xlfn.FILTERXML("<t><s>" & SUBSTITUTE(T10,",","</s><s>") & "</s></t>", "//s"),Writers!$A$3:$A$999,Writers!$B$3:$B$999,""))} -> Terry Nation | W10: =IF(V10="","",_xlfn.XLOOKUP(V10,Writers!$A$3:$A$999,Writers!$B$3:$B$999,"")) | X10: 9.9 | AA10: =IF(ISBLANK(X10),"",ROUND(X10*AE10,2)) -> 12.52 | AB10: =IF(ISBLANK(Y10),"",ROUND(Y10*AE10,2)) | AC10: =IF(ISBLANK(Z10),"",ROUND(Z10*AE10,2)) | AD10: =VLOOKUP(YEAR(Q10),Populations!$A$3:$B$999,2,0) -> 53990800 | AE10: =(Calculations!B1/AD10) -> 1.2651217 | AG10: 1 | AH10: =VLOOKUP(AG10,WikiFormats!$A$3:$B$999,2,0) -> Story | AI10: https://en.wikipedia.org/wiki/The_Daleks
A11: 9 | B11: 1 | C11: =VLOOKUP(B11,Eras!$A$3:$B$999,2,0) -> Classic | D11: 1 | E11: =VLOOKUP(D11,EpisodeFormats!$A$3:$B$999,2,0) -> Series | F11: 1 | G11: =VLOOKUP(F11,Doctors!$A$3:$B$999,2,0) -> William Hartnell | H11: 1 | I11: 1 | J11: =VLOOKUP(I11,SeasonFormats!$A$3:$B$999,2,0) -> Season | K11: 2 | L11: 2 | M11: The Daleks | N11: 5 | O11: The Expedition | P11: 9 | Q11: 1964-01-18 | R11: 24 | T11: 81 | U11: {=_xlfn.TEXTJOIN(",",TRUE,_xlfn.XLOOKUP(_xlfn.FILTERXML("<t><s>" & SUBSTITUTE(T11,",","</s><s>") & "</s></t>", "//s"),Writers!$A$3:$A$999,Writers!$B$3:$B$999,""))} -> Terry Nation | W11: =IF(V11="","",_xlfn.XLOOKUP(V11,Writers!$A$3:$A$999,Writers!$B$3:$B$999,"")) | X11: 9.9 | AA11: =IF(ISBLANK(X11),"",ROUND(X11*AE11,2)) -> 12.52 | AB11: =IF(ISBLANK(Y11),"",ROUND(Y11*AE11,2)) | AC11: =IF(ISBLANK(Z11),"",ROUND(Z11*AE11,2)) | AD11: =VLOOKUP(YEAR(Q11),Populations!$A$3:$B$999,2,0) -> 53990800 | AE11: =(Calculations!B1/AD11) -> 1.2651217 | AG11: 1 | AH11: =VLOOKUP(AG11,WikiFormats!$A$3:$B$999,2,0) -> Story | AI11: https://en.wikipedia.org/wiki/The_Daleks
A12: 10 | B12: 1 | C12: =VLOOKUP(B12,Eras!$A$3:$B$999,2,0) -> Classic | D12: 1 | E12: =VLOOKUP(D12,EpisodeFormats!$A$3:$B$999,2,0) -> Series | F12: 1 | G12: =VLOOKUP(F12,Doctors!$A$3:$B$999,2,0) -> William Hartnell | H12: 1 | I12: 1 | J12: =VLOOKUP(I12,SeasonFormats!$A$3:$B$999,2,0) -> Season | K12: 2 | L12: 2 | M12: The Daleks | N12: 6 | O12: The Ordeal | P12: 10 | Q12: 1964-01-25 | R12: 26 | T12: 81 | U12: {=_xlfn.TEXTJOIN(",",TRUE,_xlfn.XLOOKUP(_xlfn.FILTERXML("<t><s>" & SUBSTITUTE(T12,",","</s><s>") & "</s></t>", "//s"),Writers!$A$3:$A$999,Writers!$B$3:$B$999,""))} -> Terry Nation | W12: =IF(V12="","",_xlfn.XLOOKUP(V12,Writers!$A$3:$A$999,Writers!$B$3:$B$999,"")) | X12: 10.4 | AA12: =IF(ISBLANK(X12),"",ROUND(X12*AE12,2)) -> 13.16 | AB12: =IF(ISBLANK(Y12),"",ROUND(Y12*AE12,2)) | AC12: =IF(ISBLANK(Z12),"",ROUND(Z12*AE12,2)) | AD12: =VLOOKUP(YEAR(Q12),Populations!$A$3:$B$999,2,0) -> 53990800 | AE12: =(Calculations!B1/AD12) -> 1.2651217 | AG12: 1 | AH12: =VLOOKUP(AG12,WikiFormats!$A$3:$B$999,2,0) -> Story | AI12: https://en.wikipedia.org/wiki/The_Daleks
A13: 11 | B13: 1 | C13: =VLOOKUP(B13,Eras!$A$3:$B$999,2,0) -> Classic | D13: 1 | E13: =VLOOKUP(D13,EpisodeFormats!$A$3:$B$999,2,0) -> Series | F13: 1 | G13: =VLOOKUP(F13,Doctors!$A$3:$B$999,2,0) -> William Hartnell | H13: 1 | I13: 1 | J13: =VLOOKUP(I13,SeasonFormats!$A$3:$B$999,2,0) -> Season | K13: 2 | L13: 2 | M13: The Daleks | N13: 7 | O13: The Rescue | P13: 11 | Q13: 1964-02-01 | R13: 22 | T13: 81 | U13: {=_xlfn.TEXTJOIN(",",TRUE,_xlfn.XLOOKUP(_xlfn.FILTERXML("<t><s>" & SUBSTITUTE(T13,",","</s><s>") & "</s></t>", "//s"),Writers!$A$3:$A$999,Writers!$B$3:$B$999,""))} -> Terry Nation | W13: =IF(V13="","",_xlfn.XLOOKUP(V13,Writers!$A$3:$A$999,Writers!$B$3:$B$999,"")) | X13: 10.4 | AA13: =IF(ISBLANK(X13),"",ROUND(X13*AE13,2)) -> 13.16 | AB13: =IF(ISBLANK(Y13),"",ROUND(Y13*AE13,2)) | AC13: =IF(ISBLANK(Z13),"",ROUND(Z13*AE13,2)) | AD13: =VLOOKUP(YEAR(Q13),Populations!$A$3:$B$999,2,0) -> 53990800 | AE13: =(Calculations!B1/AD13) -> 1.2651217 | AG13: 1 | AH13: =VLOOKUP(AG13,WikiFormats!$A$3:$B$999,2,0) -> Story | AI13: https://en.wikipedia.org/wiki/The_Daleks
A14: 12 | B14: 1 | C14: =VLOOKUP(B14,Eras!$A$3:$B$999,2,0) -> Classic | D14: 1 | E14: =VLOOKUP(D14,EpisodeFormats!$A$3:$B$999,2,0) -> Series | F14: 1 | G14: =VLOOKUP(F14,Doctors!$A$3:$B$999,2,0) -> William Hartnell | H14: 1 | I14: 1 | J14: =VLOOKUP(I14,SeasonFormats!$A$3:$B$999,2,0) -> Season | K14: 3 | L14: 3 | M14: The Edge of Destruction | N14: 1 | O14: The Edge of Destruction | P14: 12 | Q14: 1964-02-08 | R14: 25 | T14: 109 | U14: {=_xlfn.TEXTJOIN(",",TRUE,_xlfn.XLOOKUP(_xlfn.FILTERXML("<t><s>" & SUBSTITUTE(T14,",","</s><s>") & "</s></t>", "//s"),Writers!$A$3:$A$999,Writers!$B$3:$B$999,""))} -> David Whitaker | W14: =IF(V14="","",_xlfn.XLOOKUP(V14,Writers!$A$3:$A$999,Writers!$B$3:$B$999,"")) | X14: 10.4 | AA14: =IF(ISBLANK(X14),"",ROUND(X14*AE14,2)) -> 13.16 | AB14: =IF(ISBLANK(Y14),"",ROUND(Y14*AE14,2)) | AC14: =IF(ISBLANK(Z14),"",ROUND(Z14*AE14,2)) | AD14: =VLOOKUP(YEAR(Q14),Populations!$A$3:$B$999,2,0) -> 53990800 | AE14: =(Calculations!B1/AD14) -> 1.2651217 | AG14: 1 | AH14: =VLOOKUP(AG14,WikiFormats!$A$3:$B$999,2,0) -> Story | AI14: https://en.wikipedia.org/wiki/The_Edge_of_Destruction
A15: 13 | B15: 1 | C15: =VLOOKUP(B15,Eras!$A$3:$B$999,2,0) -> Classic | D15: 1 | E15: =VLOOKUP(D15,EpisodeFormats!$A$3:$B$999,2,0) -> Series | F15: 1 | G15: =VLOOKUP(F15,Doctors!$A$3:$B$999,2,0) -> William Hartnell | H15: 1 | I15: 1 | J15: =VLOOKUP(I15,SeasonFormats!$A$3:$B$999,2,0) -> Season | K15: 3 | L15: 3 | M15: The Edge of Destruction | N15: 2 | O15: The Brink of Disaster | P15: 13 | Q15: 1964-02-15 | R15: 22 | T15: 109 | U15: {=_xlfn.TEXTJOIN(",",TRUE,_xlfn.XLOOKUP(_xlfn.FILTERXML("<t><s>" & SUBSTITUTE(T15,",","</s><s>") & "</s></t>", "//s"),Writers!$A$3:$A$999,Writers!$B$3:$B$999,""))} -> David Whitaker | W15: =IF(V15="","",_xlfn.XLOOKUP(V15,Writers!$A$3:$A$999,Writers!$B$3:$B$999,"")) | X15: 9.9 | AA15: =IF(ISBLANK(X15),"",ROUND(X15*AE15,2)) -> 12.52 | AB15: =IF(ISBLANK(Y15),"",ROUND(Y15*AE15,2)) | AC15: =IF(ISBLANK(Z15),"",ROUND(Z15*AE15,2)) | AD15: =VLOOKUP(YEAR(Q15),Populations!$A$3:$B$999,2,0) -> 53990800 | AE15: =(Calculations!B1/AD15) -> 1.2651217 | AG15: 1 | AH15: =VLOOKUP(AG15,WikiFormats!$A$3:$B$999,2,0) -> Story | AI15: https://en.wikipedia.org/wiki/The_Edge_of_Destruction
A16: 14 | B16: 1 | C16: =VLOOKUP(B16,Eras!$A$3:$B$999,2,0) -> Classic | D16: 1 | E16: =VLOOKUP(D16,EpisodeFormats!$A$3:$B$999,2,0) -> Series | F16: 1 | G16: =VLOOKUP(F16,Doctors!$A$3:$B$999,2,0) -> William Hartnell | H16: 1 | I16: 1 | J16: =VLOOKUP(I16,SeasonFormats!$A$3:$B$999,2,0) -> Season | K16: 4 | L16: 4 | M16: Marco Polo | N16: 1 | O16: The Roof of the World | P16: 14 | Q16: 1964-02-22 | R16: -25 | S16: 1 | T16: 67 | U16: {=_xlfn.TEXTJOIN(",",TRUE,_xlfn.XLOOKUP(_xlfn.FILTERXML("<t><s>" & SUBSTITUTE(T16,",","</s><s>") & "</s></t>", "//s"),Writers!$A$3:$A$999,Writers!$B$3:$B$999,""))} -> John Lucarotti | W16: =IF(V16="","",_xlfn.XLOOKUP(V16,Writers!$A$3:$A$999,Writers!$B$3:$B$999,"")) | X16: 9.4 | AA16: =IF(ISBLANK(X16),"",ROUND(X16*AE16,2)) -> 11.89 | AB16: =IF(ISBLANK(Y16),"",ROUND(Y16*AE16,2)) | AC16: =IF(ISBLANK(Z16),"",ROUND(Z16*AE16,2)) | AD16: =VLOOKUP(YEAR(Q16),Populations!$A$3:$B$999,2,0) -> 53990800 | AE16: =(Calculations!B1/AD16) -> 1.2651217 | AG16: 1 | AH16: =VLOOKUP(AG16,WikiFormats!$A$3:$B$999,2,0) -> Story | AI16: https://en.wikipedia.org/wiki/Marco_Polo_(Doctor_Who)
A17: 15 | B17: 1 | C17: =VLOOKUP(B17,Eras!$A$3:$B$999,2,0) -> Classic | D17: 1 | E17: =VLOOKUP(D17,EpisodeFormats!$A$3:$B$999,2,0) -> Series | F17: 1 | G17: =VLOOKUP(F17,Doctors!$A$3:$B$999,2,0) -> William Hartnell | H17: 1 | I17: 1 | J17: =VLOOKUP(I17,SeasonFormats!$A$3:$B$999,2,0) -> Season | K17: 4 | L17: 4 | M17: Marco Polo | N17: 2 | O17: The Singing Sands | P17: 15 | Q17: 1964-02-29 | R17: -25 | S17: 1 | T17: 67 | U17: {=_xlfn.TEXTJOIN(",",TRUE,_xlfn.XLOOKUP(_xlfn.FILTERXML("<t><s>" & SUBSTITUTE(T17,",","</s><s>") & "</s></t>", "//s"),Writers!$A$3:$A$999,Writers!$B$3:$B$999,""))} -> John Lucarotti | W17: =IF(V17="","",_xlfn.XLOOKUP(V17,Writers!$A$3:$A$999,Writers!$B$3:$B$999,"")) | X17: 9.4 | AA17: =IF(ISBLANK(X17),"",ROUND(X17*AE17,2)) -> 11.89 | AB17: =IF(ISBLANK(Y17),"",ROUND(Y17*AE17,2)) | AC17: =IF(ISBLANK(Z17),"",ROUND(Z17*AE17,2)) | AD17: =VLOOKUP(YEAR(Q17),Populations!$A$3:$B$999,2,0) -> 53990800 | AE17: =(Calculations!B1/AD17) -> 1.2651217 | AG17: 1 | AH17: =VLOOKUP(AG17,WikiFormats!$A$3:$B$999,2,0) -> Story | AI17: https://en.wikipedia.org/wiki/Marco_Polo_(Doctor_Who)
A18: 16 | B18: 1 | C18: =VLOOKUP(B18,Eras!$A$3:$B$999,2,0) -> Classic | D18: 1 | E18: =VLOOKUP(D18,EpisodeFormats!$A$3:$B$999,2,0) -> Series | F18: 1 | G18: =VLOOKUP(F18,Doctors!$A$3:$B$999,2,0) -> William Hartnell | H18: 1 | I18: 1 | J18: =VLOOKUP(I18,SeasonFormats!$A$3:$B$999,2,0) -> Season | K18: 4 | L18: 4 | M18: Marco Polo | N18: 3 | O18: Five Hundred Eyes | P18: 16 | Q18: 1964-03-07 | R18: -25 | S18: 1 | T18: 67 | U18: {=_xlfn.TEXTJOIN(",",TRUE,_xlfn.XLOOKUP(_xlfn.FILTERXML("<t><s>" & SUBSTITUTE(T18,",","</s><s>") & "</s></t>", "//s"),Writers!$A$3:$A$999,Writers!$B$3:$B$999,""))} -> John Lucarotti | W18: =IF(V18="","",_xlfn.XLOOKUP(V18,Writers!$A$3:$A$999,Writers!$B$3:$B$999,"")) | X18: 9.4 | AA18: =IF(ISBLANK(X18),"",ROUND(X18*AE18,2)) -> 11.89 | AB18: =IF(ISBLANK(Y18),"",ROUND(Y18*AE18,2)) | AC18: =IF(ISBLANK(Z18),"",ROUND(Z18*AE18,2)) | AD18: =VLOOKUP(YEAR(Q18),Populations!$A$3:$B$999,2,0) -> 53990800 | AE18: =(Calculations!B1/AD18) -> 1.2651217 | AG18: 1 | AH18: =VLOOKUP(AG18,WikiFormats!$A$3:$B$999,2,0) -> Story | AI18: https://en.wikipedia.org/wiki/Marco_Polo_(Doctor_Who)
A19: 17 | B19: 1 | C19: =VLOOKUP(B19,Eras!$A$3:$B$999,2,0) -> Classic | D19: 1 | E19: =VLOOKUP(D19,EpisodeFormats!$A$3:$B$999,2,0) -> Series | F19: 1 | G19: =VLOOKUP(F19,Doctors!$A$3:$B$999,2,0) -> William Hartnell | H19: 1 | I19: 1 | J19: =VLOOKUP(I19,SeasonFormats!$A$3:$B$999,2,0) -> Season | K19: 4 | L19: 4 | M19: Marco Polo | N19: 4 | O19: The Wall of Lies | P19: 17 | Q19: 1964-03-14 | R19: -25 | S19: 1 | T19: 67 | U19: {=_xlfn.TEXTJOIN(",",TRUE,_xlfn.XLOOKUP(_xlfn.FILTERXML("<t><s>" & SUBSTITUTE(T19,",","</s><s>") & "</s></t>", "//s"),Writers!$A$3:$A$999,Writers!$B$3:$B$999,""))} -> John Lucarotti | W19: =IF(V19="","",_xlfn.XLOOKUP(V19,Writers!$A$3:$A$999,Writers!$B$3:$B$999,"")) | X19: 9.9 | AA19: =IF(ISBLANK(X19),"",ROUND(X19*AE19,2)) -> 12.52 | AB19: =IF(ISBLANK(Y19),"",ROUND(Y19*AE19,2)) | AC19: =IF(ISBLANK(Z19),"",ROUND(Z19*AE19,2)) | AD19: =VLOOKUP(YEAR(Q19),Populations!$A$3:$B$999,2,0) -> 53990800 | AE19: =(Calculations!B1/AD19) -> 1.2651217 | AG19: 1 | AH19: =VLOOKUP(AG19,WikiFormats!$A$3:$B$999,2,0) -> Story | AI19: https://en.wikipedia.org/wiki/Marco_Polo_(Doctor_Who)
A20: 18 | B20: 1 | C20: =VLOOKUP(B20,Eras!$A$3:$B$999,2,0) -> Classic | D20: 1 | E20: =VLOOKUP(D20,EpisodeFormats!$A$3:$B$999,2,0) -> Series | F20: 1 | G20: =VLOOKUP(F20,Doctors!$A$3:$B$999,2,0) -> William Hartnell | H20: 1 | I20: 1 | J20: =VLOOKUP(I20,SeasonFormats!$A$3:$B$999,2,0) -> Season | K20: 4 | L20: 4 | M20: Marco Polo | N20: 5 | O20: Rider from Shang-Tu | P20: 18 | Q20: 1964-03-21 | R20: -25 | S20: 1 | T20: 67 | U20: {=_xlfn.TEXTJOIN(",",TRUE,_xlfn.XLOOKUP(_xlfn.FILTERXML("<t><s>" & SUBSTITUTE(T20,",","</s><s>") & "</s></t>", "//s"),Writers!$A$3:$A$999,Writers!$B$3:$B$999,""))} -> John Lucarotti | W20: =IF(V20="","",_xlfn.XLOOKUP(V20,Writers!$A$3:$A$999,Writers!$B$3:$B$999,"")) | X20: 9.4 | AA20: =IF(ISBLANK(X20),"",ROUND(X20*AE20,2)) -> 11.89 | AB20: =IF(ISBLANK(Y20),"",ROUND(Y20*AE20,2)) | AC20: =IF(ISBLANK(Z20),"",ROUND(Z20*AE20,2)) | AD20: =VLOOKUP(YEAR(Q20),Populations!$A$3:$B$999,2,0) -> 53990800 | AE20: =(Calculations!B1/AD20) -> 1.2651217 | AG20: 1 | AH20: =VLOOKUP(AG20,WikiFormats!$A$3:$B$999,2,0) -> Story | AI20: https://en.wikipedia.org/wiki/Marco_Polo_(Doctor_Who)
A21: 19 | B21: 1 | C21: =VLOOKUP(B21,Eras!$A$3:$B$999,2,0) -> Classic | D21: 1 | E21: =VLOOKUP(D21,EpisodeFormats!$A$3:$B$999,2,0) -> Series | F21: 1 | G21: =VLOOKUP(F21,Doctors!$A$3:$B$999,2,0) -> William Hartnell | H21: 1 | I21: 1 | J21: =VLOOKUP(I21,SeasonFormats!$A$3:$B$999,2,0) -> Season | K21: 4 | L21: 4 | M21: Marco Polo | N21: 6 | O21: Mighty Kublai Khan | P21: 19 | Q21: 1964-03-28 | R21: -25 | S21: 1 | T21: 67 | U21: {=_xlfn.TEXTJOIN(",",TRUE,_xlfn.XLOOKUP(_xlfn.FILTERXML("<t><s>" & SUBSTITUTE(T21,",","</s><s>") & "</s></t>", "//s"),Writers!$A$3:$A$999,Writers!$B$3:$B$999,""))} -> John Lucarotti | W21: =IF(V21="","",_xlfn.XLOOKUP(V21,Writers!$A$3:$A$999,Writers!$B$3:$B$999,"")) | X21: 8.4 | AA21: =IF(ISBLANK(X21),"",ROUND(X21*AE21,2)) -> 10.63 | AB21: =IF(ISBLANK(Y21),"",ROUND(Y21*AE21,2)) | AC21: =IF(ISBLANK(Z21),"",ROUND(Z21*AE21,2)) | AD21: =VLOOKUP(YEAR(Q21),Populations!$A$3:$B$999,2,0) -> 53990800 | AE21: =(Calculations!B1/AD21) -> 1.2651217 | AG21: 1 | AH21: =VLOOKUP(AG21,WikiFormats!$A$3:$B$999,2,0) -> Story | AI21: https://en.wikipedia.org/wiki/Marco_Polo_(Doctor_Who)
A22: 20 | B22: 1 | C22: =VLOOKUP(B22,Eras!$A$3:$B$999,2,0) -> Classic | D22: 1 | E22: =VLOOKUP(D22,EpisodeFormats!$A$3:$B$999,2,0) -> Series | F22: 1 | G22: =VLOOKUP(F22,Doctors!$A$3:$B$999,2,0) -> William Hartnell | H22: 1 | I22: 1 | J22: =VLOOKUP(I22,SeasonFormats!$A$3:$B$999,2,0) -> Season | K22: 4 | L22: 4 | M22: Marco Polo | N22: 7 | O22: Assassin at Peking | P22: 20 | Q22: 1964-04-04 | R22: -25 | S22: 1 | T22: 67 | U22: {=_xlfn.TEXTJOIN(",",TRUE,_xlfn.XLOOKUP(_xlfn.FILTERXML("<t><s>" & SUBSTITUTE(T22,",","</s><s>") & "</s></t>", "//s"),Writers!$A$3:$A$999,Writers!$B$3:$B$999,""))} -> John Lucarotti | W22: =IF(V22="","",_xlfn.XLOOKUP(V22,Writers!$A$3:$A$999,Writers!$B$3:$B$999,"")) | X22: 10.4 | AA22: =IF(ISBLANK(X22),"",ROUND(X22*AE22,2)) -> 13.16 | AB22: =IF(ISBLANK(Y22),"",ROUND(Y22*AE22,2)) | AC22: =IF(ISBLANK(Z22),"",ROUND(Z22*AE22,2)) | AD22: =VLOOKUP(YEAR(Q22),Populations!$A$3:$B$999,2,0) -> 53990800 | AE22: =(Calculations!B1/AD22) -> 1.2651217 | AG22: 1 | AH22: =VLOOKUP(AG22,WikiFormats!$A$3:$B$999,2,0) -> Story | AI22: https://en.wikipedia.org/wiki/Marco_Polo_(Doctor_Who)
A23: 21 | B23: 1 | C23: =VLOOKUP(B23,Eras!$A$3:$B$999,2,0) -> Classic | D23: 1 | E23: =VLOOKUP(D23,EpisodeFormats!$A$3:$B$999,2,0) -> Series | F23: 1 | G23: =VLOOKUP(F23,Doctors!$A$3:$B$999,2,0) -> William Hartnell | H23: 1 | I23: 1 | J23: =VLOOKUP(I23,SeasonFormats!$A$3:$B$999,2,0) -> Season | K23: 5 | L23: 5 | M23: The Keys of Marinus | N23: 1 | O23: The Sea of Death | P23: 21 | Q23: 1964-04-11 | R23: 23 | T23: 81 | U23: {=_xlfn.TEXTJOIN(",",TRUE,_xlfn.XLOOKUP(_xlfn.FILTERXML("<t><s>" & SUBSTITUTE(T23,",","</s><s>") & "</s></t>", "//s"),Writers!$A$3:$A$999,Writers!$B$3:$B$999,""))} -> Terry Nation | W23: =IF(V23="","",_xlfn.XLOOKUP(V23,Writers!$A$3:$A$999,Writers!$B$3:$B$999,"")) | X23: 9.9 | AA23: =IF(ISBLANK(X23),"",ROUND(X23*AE23,2)) -> 12.52 | AB23: =IF(ISBLANK(Y23),"",ROUND(Y23*AE23,2)) | AC23: =IF(ISBLANK(Z23),"",ROUND(Z23*AE23,2)) | AD23: =VLOOKUP(YEAR(Q23),Populations!$A$3:$B$999,2,0) -> 53990800 | AE23: =(Calculations!B1/AD23) -> 1.2651217 | AG23: 1 | AH23: =VLOOKUP(AG23,WikiFormats!$A$3:$B$999,2,0) -> Story | AI23: https://en.wikipedia.org/wiki/The_Keys_of_Marinus
A24: 22 | B24: 1 | C24: =VLOOKUP(B24,Eras!$A$3:$B$999,2,0) -> Classic | D24: 1 | E24: =VLOOKUP(D24,EpisodeFormats!$A$3:$B$999,2,0) -> Series | F24: 1 | G24: =VLOOKUP(F24,Doctors!$A$3:$B$999,2,0) -> William Hartnell | H24: 1 | I24: 1 | J24: =VLOOKUP(I24,SeasonFormats!$A$3:$B$999,2,0) -> Season | K24: 5 | L24: 5 | M24: The Keys of Marinus | N24: 2 | O24: The Velvet Web | P24: 22 | Q24: 1964-04-18 | R24: 25 | T24: 81 | U24: {=_xlfn.TEXTJOIN(",",TRUE,_xlfn.XLOOKUP(_xlfn.FILTERXML("<t><s>" & SUBSTITUTE(T24,",","</s><s>") & "</s></t>", "//s"),Writers!$A$3:$A$999,Writers!$B$3:$B$999,""))} -> Terry Nation | W24: =IF(V24="","",_xlfn.XLOOKUP(V24,Writers!$A$3:$A$999,Writers!$B$3:$B$999,"")) | X24: 9.4 | AA24: =IF(ISBLANK(X24),"",ROUND(X24*AE24,2)) -> 11.89 | AB24: =IF(ISBLANK(Y24),"",ROUND(Y24*AE24,2)) | AC24: =IF(ISBLANK(Z24),"",ROUND(Z24*AE24,2)) | AD24: =VLOOKUP(YEAR(Q24),Populations!$A$3:$B$999,2,0) -> 53990800 | AE24: =(Calculations!B1/AD24) -> 1.2651217 | AG24: 1 | AH24: =VLOOKUP(AG24,WikiFormats!$A$3:$B$999,2,0) -> Story | AI24: https://en.wikipedia.org/wiki/The_Keys_of_Marinus
A25: 23 | B25: 1 | C25: =VLOOKUP(B25,Eras!$A$3:$B$999,2,0) -> Classic | D25: 1 | E25: =VLOOKUP(D25,EpisodeFormats!$A$3:$B$999,2,0) -> Series | F25: 1 | G25: =VLOOKUP(F25,Doctors!$A$3:$B$999,2,0) -> William Hartnell | H25: 1 | I25: 1 | J25: =VLOOKUP(I25,SeasonFormats!$A$3:$B$999,2,0) -> Season | K25: 5 | L25: 5 | M25: The Keys of Marinus | N25: 3 | O25: The Screaming Jungle | P25: 23 | Q25: 1964-04-25 | R25: 24 | T25: 81 | U25: {=_xlfn.TEXTJOIN(",",TRUE,_xlfn.XLOOKUP(_xlfn.FILTERXML("<t><s>" & SUBSTITUTE(T25,",","</s><s>") & "</s></t>", "//s"),Writers!$A$3:$A$999,Writers!$B$3:$B$999,""))} -> Terry Nation | W25: =IF(V25="","",_xlfn.XLOOKUP(V25,Writers!$A$3:$A$999,Writers!$B$3:$B$999,"")) | X25: 9.9 | AA25: =IF(ISBLANK(X25),"",ROUND(X25*AE25,2)) -> 12.52 | AB25: =IF(ISBLANK(Y25),"",ROUND(Y25*AE25,2)) | AC25: =IF(ISBLANK(Z25),"",ROUND(Z25*AE25,2)) | AD25: =VLOOKUP(YEAR(Q25),Populations!$A$3:$B$999,2,0) -> 53990800 | AE25: =(Calculations!B1/AD25) -> 1.2651217 | AG25: 1 | AH25: =VLOOKUP(AG25,WikiFormats!$A$3:$B$999,2,0) -> Story | AI25: https://en.wikipedia.org/wiki/The_Keys_of_Marinus
A26: 24 | B26: 1 | C26: =VLOOKUP(B26,Eras!$A$3:$B$999,2,0) -> Classic | D26: 1 | E26: =VLOOKUP(D26,EpisodeFormats!$A$3:$B$999,2,0) -> Series | F26: 1 | G26: =VLOOKUP(F26,Doctors!$A$3:$B$999,2,0) -> William Hartnell | H26: 1 | I26: 1 | J26: =VLOOKUP(I26,SeasonFormats!$A$3:$B$999,2,0) -> Season | K26: 5 | L26: 5 | M26: The Keys of Marinus | N26: 4 | O26: The Snows of Terror | P26: 24 | Q26: 1964-05-02 | R26: 25 | T26: 81 | U26: {=_xlfn.TEXTJOIN(",",TRUE,_xlfn.XLOOKUP(_xlfn.FILTERXML("<t><s>" & SUBSTITUTE(T26,",","</s><s>") & "</s></t>", "//s"),Writers!$A$3:$A$999,Writers!$B$3:$B$999,""))} -> Terry Nation | W26: =IF(V26="","",_xlfn.XLOOKUP(V26,Writers!$A$3:$A$999,Writers!$B$3:$B$999,"")) | X26: 10.4 | AA26: =IF(ISBLANK(X26),"",ROUND(X26*AE26,2)) -> 13.16 | AB26: =IF(ISBLANK(Y26),"",ROUND(Y26*AE26,2)) | AC26: =IF(ISBLANK(Z26),"",ROUND(Z26*AE26,2)) | AD26: =VLOOKUP(YEAR(Q26),Populations!$A$3:$B$999,2,0) -> 53990800 | AE26: =(Calculations!B1/AD26) -> 1.2651217 | AG26: 1 | AH26: =VLOOKUP(AG26,WikiFormats!$A$3:$B$999,2,0) -> Story | AI26: https://en.wikipedia.org/wiki/The_Keys_of_Marinus
A27: 25 | B27: 1 | C27: =VLOOKUP(B27,Eras!$A$3:$B$999,2,0) -> Classic | D27: 1 | E27: =VLOOKUP(D27,EpisodeFormats!$A$3:$B$999,2,0) -> Series | F27: 1 | G27: =VLOOKUP(F27,Doctors!$A$3:$B$999,2,0) -> William Hartnell | H27: 1 | I27: 1 | J27: =VLOOKUP(I27,SeasonFormats!$A$3:$B$999,2,0) -> Season | K27: 5 | L27: 5 | M27: The Keys of Marinus | N27: 5 | O27: Sentence of Death | P27: 25 | Q27: 1964-05-09 | R27: 25 | T27: 81 | U27: {=_xlfn.TEXTJOIN(",",TRUE,_xlfn.XLOOKUP(_xlfn.FILTERXML("<t><s>" & SUBSTITUTE(T27,",","</s><s>") & "</s></t>", "//s"),Writers!$A$3:$A$999,Writers!$B$3:$B$999,""))} -> Terry Nation | W27: =IF(V27="","",_xlfn.XLOOKUP(V27,Writers!$A$3:$A$999,Writers!$B$3:$B$999,"")) | X27: 7.9 | AA27: =IF(ISBLANK(X27),"",ROUND(X27*AE27,2)) -> 9.99 | AB27: =IF(ISBLANK(Y27),"",ROUND(Y27*AE27,2)) | AC27: =IF(ISBLANK(Z27),"",ROUND(Z27*AE27,2)) | AD27: =VLOOKUP(YEAR(Q27),Populations!$A$3:$B$999,2,0) -> 53990800 | AE27: =(Calculations!B1/AD27) -> 1.2651217 | AG27: 1 | AH27: =VLOOKUP(AG27,WikiFormats!$A$3:$B$999,2,0) -> Story | AI27: https://en.wikipedia.org/wiki/The_Keys_of_Marinus
A28: 26 | B28: 1 | C28: =VLOOKUP(B28,Eras!$A$3:$B$999,2,0) -> Classic | D28: 1 | E28: =VLOOKUP(D28,EpisodeFormats!$A$3:$B$999,2,0) -> Series | F28: 1 | G28: =VLOOKUP(F28,Doctors!$A$3:$B$999,2,0) -> William Hartnell | H28: 1 | I28: 1 | J28: =VLOOKUP(I28,SeasonFormats!$A$3:$B$999,2,0) -> Season | K28: 5 | L28: 5 | M28: The Keys of Marinus | N28: 6 | O28: The Keys of Marinus | P28: 26 | Q28: 1964-05-16 | R28: 25 | T28: 81 | U28: {=_xlfn.TEXTJOIN(",",TRUE,_xlfn.XLOOKUP(_xlfn.FILTERXML("<t><s>" & SUBSTITUTE(T28,",","</s><s>") & "</s></t>", "//s"),Writers!$A$3:$A$999,Writers!$B$3:$B$999,""))} -> Terry Nation | W28: =IF(V28="","",_xlfn.XLOOKUP(V28,Writers!$A$3:$A$999,Writers!$B$3:$B$999,"")) | X28: 6.9 | AA28: =IF(ISBLANK(X28),"",ROUND(X28*AE28,2)) -> 8.73 | AB28: =IF(ISBLANK(Y28),"",ROUND(Y28*AE28,2)) | AC28: =IF(ISBLANK(Z28),"",ROUND(Z28*AE28,2)) | AD28: =VLOOKUP(YEAR(Q28),Populations!$A$3:$B$999,2,0) -> 53990800 | AE28: =(Calculations!B1/AD28) -> 1.2651217 | AG28: 1 | AH28: =VLOOKUP(AG28,WikiFormats!$A$3:$B$999,2,0) -> Story | AI28: https://en.wikipedia.org/wiki/The_Keys_of_Marinus
A29: 27 | B29: 1 | C29: =VLOOKUP(B29,Eras!$A$3:$B$999,2,0) -> Classic | D29: 1 | E29: =VLOOKUP(D29,EpisodeFormats!$A$3:$B$999,2,0) -> Series | F29: 1 | G29: =VLOOKUP(F29,Doctors!$A$3:$B$999,2,0) -> William Hartnell | H29: 1 | I29: 1 | J29: =VLOOKUP(I29,SeasonFormats!$A$3:$B$999,2,0) -> Season | K29: 6 | L29: 6 | M29: The Aztecs | N29: 1 | O29: The Temple of Evil | P29: 27 | Q29: 1964-05-23 | R29: 24 | T29: 67 | U29: {=_xlfn.TEXTJOIN(",",TRUE,_xlfn.XLOOKUP(_xlfn.FILTERXML("<t><s>" & SUBSTITUTE(T29,",","</s><s>") & "</s></t>", "//s"),Writers!$A$3:$A$999,Writers!$B$3:$B$999,""))} -> John Lucarotti | W29: =IF(V29="","",_xlfn.XLOOKUP(V29,Writers!$A$3:$A$999,Writers!$B$3:$B$999,"")) | X29: 7.4 | AA29: =IF(ISBLANK(X29),"",ROUND(X29*AE29,2)) -> 9.36 | AB29: =IF(ISBLANK(Y29),"",ROUND(Y29*AE29,2)) | AC29: =IF(ISBLANK(Z29),"",ROUND(Z29*AE29,2)) | AD29: =VLOOKUP(YEAR(Q29),Populations!$A$3:$B$999,2,0) -> 53990800 | AE29: =(Calculations!B1/AD29) -> 1.2651217 | AG29: 1 | AH29: =VLOOKUP(AG29,WikiFormats!$A$3:$B$999,2,0) -> Story | AI29: https://en.wikipedia.org/wiki/The_Aztecs_(Doctor_Who)
A30: 28 | B30: 1 | C30: =VLOOKUP(B30,Eras!$A$3:$B$999,2,0) -> Classic | D30: 1 | E30: =VLOOKUP(D30,EpisodeFormats!$A$3:$B$999,2,0) -> Series | F30: 1 | G30: =VLOOKUP(F30,Doctors!$A$3:$B$999,2,0) -> William Hartnell | H30: 1 | I30: 1 | J30: =VLOOKUP(I30,SeasonFormats!$A$3:$B$999,2,0) -> Season | K30: 6 | L30: 6 | M30: The Aztecs | N30: 2 | O30: The Warriors of Death | P30: 28 | Q30: 1964-05-30 | R30: 24 | T30: 67 | U30: {=_xlfn.TEXTJOIN(",",TRUE,_xlfn.XLOOKUP(_xlfn.FILTERXML("<t><s>" & SUBSTITUTE(T30,",","</s><s>") & "</s></t>", "//s"),Writers!$A$3:$A$999,Writers!$B$3:$B$999,""))} -> John Lucarotti | W30: =IF(V30="","",_xlfn.XLOOKUP(V30,Writers!$A$3:$A$999,Writers!$B$3:$B$999,"")) | X30: 7.4 | AA30: =IF(ISBLANK(X30),"",ROUND(X30*AE30,2)) -> 9.36 | AB30: =IF(ISBLANK(Y30),"",ROUND(Y30*AE30,2)) | AC30: =IF(ISBLANK(Z30),"",ROUND(Z30*AE30,2)) | AD30: =VLOOKUP(YEAR(Q30),Populations!$A$3:$B$999,2,0) -> 53990800 | AE30: =(Calculations!B1/AD30) -> 1.2651217 | AG30: 1 | AH30: =VLOOKUP(AG30,WikiFormats!$A$3:$B$999,2,0) -> Story | AI30: https://en.wikipedia.org/wiki/The_Aztecs_(Doctor_Who)
A31: 29 | B31: 1 | C31: =VLOOKUP(B31,Eras!$A$3:$B$999,2,0) -> Classic | D31: 1 | E31: =VLOOKUP(D31,EpisodeFormats!$A$3:$B$999,2,0) -> Series | F31: 1 | G31: =VLOOKUP(F31,Doctors!$A$3:$B$999,2,0) -> William Hartnell | H31: 1 | I31: 1 | J31: =VLOOKUP(I31,SeasonFormats!$A$3:$B$999,2,0) -> Season | K31: 6 | L31: 6 | M31: The Aztecs | N31: 3 | O31: The Bride of Sacrifice | P31: 29 | Q31: 1964-06-06 | R31: 25 | T31: 67 | U31: {=_xlfn.TEXTJOIN(",",TRUE,_xlfn.XLOOKUP(_xlfn.FILTERXML("<t><s>" & SUBSTITUTE(T31,",","</s><s>") & "</s></t>", "//s"),Writers!$A$3:$A$999,Writers!$B$3:$B$999,""))} -> John Lucarotti | W31: =IF(V31="","",_xlfn.XLOOKUP(V31,Writers!$A$3:$A$999,Writers!$B$3:$B$999,"")) | X31: 7.9 | AA31: =IF(ISBLANK(X31),"",ROUND(X31*AE31,2)) -> 9.99 | AB31: =IF(ISBLANK(Y31),"",ROUND(Y31*AE31,2)) | AC31: =IF(ISBLANK(Z31),"",ROUND(Z31*AE31,2)) | AD31: =VLOOKUP(YEAR(Q31),Populations!$A$3:$B$999,2,0) -> 53990800 | AE31: =(Calculations!B1/AD31) -> 1.2651217 | AG31: 1 | AH31: =VLOOKUP(AG31,WikiFormats!$A$3:$B$999,2,0) -> Story | AI31: https://en.wikipedia.org/wiki/The_Aztecs_(Doctor_Who)
A32: 30 | B32: 1 | C32: =VLOOKUP(B32,Eras!$A$3:$B$999,2,0) -> Classic | D32: 1 | E32: =VLOOKUP(D32,EpisodeFormats!$A$3:$B$999,2,0) -> Series | F32: 1 | G32: =VLOOKUP(F32,Doctors!$A$3:$B$999,2,0) -> William Hartnell | H32: 1 | I32: 1 | J32: =VLOOKUP(I32,SeasonFormats!$A$3:$B$999,2,0) -> Season | K32: 6 | L32: 6 | M32: The Aztecs | N32: 4 | O32: The Day of Darkness | P32: 30 | Q32: 1964-06-13 | R32: 25 | T32: 67 | U32: {=_xlfn.TEXTJOIN(",",TRUE,_xlfn.XLOOKUP(_xlfn.FILTERXML("<t><s>" & SUBSTITUTE(T32,",","</s><s>") & "</s></t>", "//s"),Writers!$A$3:$A$999,Writers!$B$3:$B$999,""))} -> John Lucarotti | W32: =IF(V32="","",_xlfn.XLOOKUP(V32,Writers!$A$3:$A$999,Writers!$B$3:$B$999,"")) | X32: 7.4 | AA32: =IF(ISBLANK(X32),"",ROUND(X32*AE32,2)) -> 9.36 | AB32: =IF(ISBLANK(Y32),"",ROUND(Y32*AE32,2)) | AC32: =IF(ISBLANK(Z32),"",ROUND(Z32*AE32,2)) | AD32: =VLOOKUP(YEAR(Q32),Populations!$A$3:$B$999,2,0) -> 53990800 | AE32: =(Calculations!B1/AD32) -> 1.2651217 | AG32: 1 | AH32: =VLOOKUP(AG32,WikiFormats!$A$3:$B$999,2,0) -> Story | AI32: https://en.wikipedia.org/wiki/The_Aztecs_(Doctor_Who)
A33: 31 | B33: 1 | C33: =VLOOKUP(B33,Eras!$A$3:$B$999,2,0) -> Classic | D33: 1 | E33: =VLOOKUP(D33,EpisodeFormats!$A$3:$B$999,2,0) -> Series | F33: 1 | G33: =VLOOKUP(F33,Doctors!$A$3:$B$999,2,0) -> William Hartnell | H33: 1 | I33: 1 | J33: =VLOOKUP(I33,SeasonFormats!$A$3:$B$999,2,0) -> Season | K33: 7 | L33: 7 | M33: The Sensorites | N33: 1 | O33: Strangers in Space | P33: 31 | Q33: 1964-06-20 | R33: 25 | T33: 82 | U33: {=_xlfn.TEXTJOIN(",",TRUE,_xlfn.XLOOKUP(_xlfn.FILTERXML("<t><s>" & SUBSTITUTE(T33,",","</s><s>") & "</s></t>", "//s"),Writers!$A$3:$A$999,Writers!$B$3:$B$999,""))} -> Peter R. Newman | W33: =IF(V33="","",_xlfn.XLOOKUP(V33,Writers!$A$3:$A$999,Writers!$B$3:$B$999,"")) | X33: 7.9 | AA33: =IF(ISBLANK(X33),"",ROUND(X33*AE33,2)) -> 9.99 | AB33: =IF(ISBLANK(Y33),"",ROUND(Y33*AE33,2)) | AC33: =IF(ISBLANK(Z33),"",ROUND(Z33*AE33,2)) | AD33: =VLOOKUP(YEAR(Q33),Populations!$A$3:$B$999,2,0) -> 53990800 | AE33: =(Calculations!B1/AD33) -> 1.2651217 | AG33: 1 | AH33: =VLOOKUP(AG33,WikiFormats!$A$3:$B$999,2,0) -> Story | AI33: https://en.wikipedia.org/wiki/The_Sensorites
A34: 32 | B34: 1 | C34: =VLOOKUP(B34,Eras!$A$3:$B$999,2,0) -> Classic | D34: 1 | E34: =VLOOKUP(D34,EpisodeFormats!$A$3:$B$999,2,0) -> Series | F34: 1 | G34: =VLOOKUP(F34,Doctors!$A$3:$B$999,2,0) -> William Hartnell | H34: 1 | I34: 1 | J34: =VLOOKUP(I34,SeasonFormats!$A$3:$B$999,2,0) -> Season | K34: 7 | L34: 7 | M34: The Sensorites | N34: 2 | O34: The Unwilling Warriors | P34: 32 | Q34: 1964-06-27 | R34: 25 | T34: 82 | U34: {=_xlfn.TEXTJOIN(",",TRUE,_xlfn.XLOOKUP(_xlfn.FILTERXML("<t><s>" & SUBSTITUTE(T34,",","</s><s>") & "</s></t>", "//s"),Writers!$A$3:$A$999,Writers!$B$3:$B$999,""))} -> Peter R. Newman | W34: =IF(V34="","",_xlfn.XLOOKUP(V34,Writers!$A$3:$A$999,Writers!$B$3:$B$999,"")) | X34: 6.9 | AA34: =IF(ISBLANK(X34),"",ROUND(X34*AE34,2)) -> 8.73 | AB34: =IF(ISBLANK(Y34),"",ROUND(Y34*AE34,2)) | AC34: =IF(ISBLANK(Z34),"",ROUND(Z34*AE34,2)) | AD34: =VLOOKUP(YEAR(Q34),Populations!$A$3:$B$999,2,0) -> 53990800 | AE34: =(Calculations!B1/AD34) -> 1.2651217 | AG34: 1 | AH34: =VLOOKUP(AG34,WikiFormats!$A$3:$B$999,2,0) -> Story | AI34: https://en.wikipedia.org/wiki/The_Sensorites
A35: 33 | B35: 1 | C35: =VLOOKUP(B35,Eras!$A$3:$B$999,2,0) -> Classic | D35: 1 | E35: =VLOOKUP(D35,EpisodeFormats!$A$3:$B$999,2,0) -> Series | F35: 1 | G35: =VLOOKUP(F35,Doctors!$A$3:$B$999,2,0) -> William Hartnell | H35: 1 | I35: 1 | J35: =VLOOKUP(I35,SeasonFormats!$A$3:$B$999,2,0) -> Season | K35: 7 | L35: 7 | M35: The Sensorites | N35: 3 | O35: Hidden Danger | P35: 33 | Q35: 1964-07-11 | R35: 25 | T35: 82 | U35: {=_xlfn.TEXTJOIN(",",TRUE,_xlfn.XLOOKUP(_xlfn.FILTERXML("<t><s>" & SUBSTITUTE(T35,",","</s><s>") & "</s></t>", "//s"),Writers!$A$3:$A$999,Writers!$B$3:$B$999,""))} -> Peter R. Newman | W35: =IF(V35="","",_xlfn.XLOOKUP(V35,Writers!$A$3:$A$999,Writers!$B$3:$B$999,"")) | X35: 7.4 | AA35: =IF(ISBLANK(X35),"",ROUND(X35*AE35,2)) -> 9.36 | AB35: =IF(ISBLANK(Y35),"",ROUND(Y35*AE35,2)) | AC35: =IF(ISBLANK(Z35),"",ROUND(Z35*AE35,2)) | AD35: =VLOOKUP(YEAR(Q35),Populations!$A$3:$B$999,2,0) -> 53990800 | AE35: =(Calculations!B1/AD35) -> 1.2651217 | AG35: 1 | AH35: =VLOOKUP(AG35,WikiFormats!$A$3:$B$999,2,0) -> Story | AI35: https://en.wikipedia.org/wiki/The_Sensorites
A36: 34 | B36: 1 | C36: =VLOOKUP(B36,Eras!$A$3:$B$999,2,0) -> Classic | D36: 1 | E36: =VLOOKUP(D36,EpisodeFormats!$A$3:$B$999,2,0) -> Series | F36: 1 | G36: =VLOOKUP(F36,Doctors!$A$3:$B$999,2,0) -> William Hartnell | H36: 1 | I36: 1 | J36: =VLOOKUP(I36,SeasonFormats!$A$3:$B$999,2,0) -> Season | K36: 7 | L36: 7 | M36: The Sensorites | N36: 4 | O36: A Race Against Death | P36: 34 | Q36: 1964-07-18 | R36: 25 | T36: 82 | U36: {=_xlfn.TEXTJOIN(",",TRUE,_xlfn.XLOOKUP(_xlfn.FILTERXML("<t><s>" & SUBSTITUTE(T36,",","</s><s>") & "</s></t>", "//s"),Writers!$A$3:$A$999,Writers!$B$3:$B$999,""))} -> Peter R. Newman | W36: =IF(V36="","",_xlfn.XLOOKUP(V36,Writers!$A$3:$A$999,Writers!$B$3:$B$999,"")) | X36: 5.5 | AA36: =IF(ISBLANK(X36),"",ROUND(X36*AE36,2)) -> 6.96 | AB36: =IF(ISBLANK(Y36),"",ROUND(Y36*AE36,2)) | AC36: =IF(ISBLANK(Z36),"",ROUND(Z36*AE36,2)) | AD36: =VLOOKUP(YEAR(Q36),Populations!$A$3:$B$999,2,0) -> 53990800 | AE36: =(Calculations!B1/AD36) -> 1.2651217 | AG36: 1 | AH36: =VLOOKUP(AG36,WikiFormats!$A$3:$B$999,2,0) -> Story | AI36: https://en.wikipedia.org/wiki/The_Sensorites
A37: 35 | B37: 1 | C37: =VLOOKUP(B37,Eras!$A$3:$B$999,2,0) -> Classic | D37: 1 | E37: =VLOOKUP(D37,EpisodeFormats!$A$3:$B$999,2,0) -> Series | F37: 1 | G37: =VLOOKUP(F37,Doctors!$A$3:$B$999,2,0) -> William Hartnell | H37: 1 | I37: 1 | J37: =VLOOKUP(I37,SeasonFormats!$A$3:$B$999,2,0) -> Season | K37: 7 | L37: 7 | M37: The Sensorites | N37: 5 | O37: Kidnap | P37: 35 | Q37: 1964-07-25 | R37: 26 | T37: 82 | U37: {=_xlfn.TEXTJOIN(",",TRUE,_xlfn.XLOOKUP(_xlfn.FILTERXML("<t><s>" & SUBSTITUTE(T37,",","</s><s>") & "</s></t>", "//s"),Writers!$A$3:$A$999,Writers!$B$3:$B$999,""))} -> Peter R. Newman | W37: =IF(V37="","",_xlfn.XLOOKUP(V37,Writers!$A$3:$A$999,Writers!$B$3:$B$999,"")) | X37: 6.9 | AA37: =IF(ISBLANK(X37),"",ROUND(X37*AE37,2)) -> 8.73 | AB37: =IF(ISBLANK(Y37),"",ROUND(Y37*AE37,2)) | AC37: =IF(ISBLANK(Z37),"",ROUND(Z37*AE37,2)) | AD37: =VLOOKUP(YEAR(Q37),Populations!$A$3:$B$999,2,0) -> 53990800 | AE37: =(Calculations!B1/AD37) -> 1.2651217 | AG37: 1 | AH37: =VLOOKUP(AG37,WikiFormats!$A$3:$B$999,2,0) -> Story | AI37: https://en.wikipedia.org/wiki/The_Sensorites
A38: 36 | B38: 1 | C38: =VLOOKUP(B38,Eras!$A$3:$B$999,2,0) -> Classic | D38: 1 | E38: =VLOOKUP(D38,EpisodeFormats!$A$3:$B$999,2,0) -> Series | F38: 1 | G38: =VLOOKUP(F38,Doctors!$A$3:$B$999,2,0) -> William Hartnell | H38: 1 | I38: 1 | J38: =VLOOKUP(I38,SeasonFormats!$A$3:$B$999,2,0) -> Season | K38: 7 | L38: 7 | M38: The Sensorites | N38: 6 | O38: A Desperate Venture | P38: 36 | Q38: 1964-08-01 | R38: 25 | T38: 82 | U38: {=_xlfn.TEXTJOIN(",",TRUE,_xlfn.XLOOKUP(_xlfn.FILTERXML("<t><s>" & SUBSTITUTE(T38,",","</s><s>") & "</s></t>", "//s"),Writers!$A$3:$A$999,Writers!$B$3:$B$999,""))} -> Peter R. Newman | W38: =IF(V38="","",_xlfn.XLOOKUP(V38,Writers!$A$3:$A$999,Writers!$B$3:$B$999,"")) | X38: 6.9 | AA38: =IF(ISBLANK(X38),"",ROUND(X38*AE38,2)) -> 8.73 | AB38: =IF(ISBLANK(Y38),"",ROUND(Y38*AE38,2)) | AC38: =IF(ISBLANK(Z38),"",ROUND(Z38*AE38,2)) | AD38: =VLOOKUP(YEAR(Q38),Populations!$A$3:$B$999,2,0) -> 53990800 | AE38: =(Calculations!B1/AD38) -> 1.2651217 | AG38: 1 | AH38: =VLOOKUP(AG38,WikiFormats!$A$3:$B$999,2,0) -> Story | AI38: https://en.wikipedia.org/wiki/The_Sensorites
A39: 37 | B39: 1 | C39: =VLOOKUP(B39,Eras!$A$3:$B$999,2,0) -> Classic | D39: 1 | E39: =VLOOKUP(D39,EpisodeFormats!$A$3:$B$999,2,0) -> Series | F39: 1 | G39: =VLOOKUP(F39,Doctors!$A$3:$B$999,2,0) -> William Hartnell | H39: 1 | I39: 1 | J39: =VLOOKUP(I39,SeasonFormats!$A$3:$B$999,2,0) -> Season | K39: 8 | L39: 8 | M39: The Reign of Terror | N39: 1 | O39: A Land of Fear | P39: 37 | Q39: 1964-08-08 | R39: 24 | T39: 101 | U39: {=_xlfn.TEXTJOIN(",",TRUE,_xlfn.XLOOKUP(_xlfn.FILTERXML("<t><s>" & SUBSTITUTE(T39,",","</s><s>") & "</s></t>", "//s"),Writers!$A$3:$A$999,Writers!$B$3:$B$999,""))} -> Dennis Spooner | W39: =IF(V39="","",_xlfn.XLOOKUP(V39,Writers!$A$3:$A$999,Writers!$B$3:$B$999,"")) | X39: 6.9 | AA39: =IF(ISBLANK(X39),"",ROUND(X39*AE39,2)) -> 8.73 | AB39: =IF(ISBLANK(Y39),"",ROUND(Y39*AE39,2)) | AC39: =IF(ISBLANK(Z39),"",ROUND(Z39*AE39,2)) | AD39: =VLOOKUP(YEAR(Q39),Populations!$A$3:$B$999,2,0) -> 53990800 | AE39: =(Calculations!B1/AD39) -> 1.2651217 | AG39: 1 | AH39: =VLOOKUP(AG39,WikiFormats!$A$3:$B$999,2,0) -> Story | AI39: https://en.wikipedia.org/wiki/The_Reign_of_Terror_(Doctor_Who)
A40: 38 | B40: 1 | C40: =VLOOKUP(B40,Eras!$A$3:$B$999,2,0) -> Classic | D40: 1 | E40: =VLOOKUP(D40,EpisodeFormats!$A$3:$B$999,2,0) -> Series | F40: 1 | G40: =VLOOKUP(F40,Doctors!$A$3:$B$999,2,0) -> William Hartnell | H40: 1 | I40: 1 | J40: =VLOOKUP(I40,SeasonFormats!$A$3:$B$999,2,0) -> Season | K40: 8 | L40: 8 | M40: The Reign of Terror | N40: 2 | O40: Guests of Madame Guillotine | P40: 38 | Q40: 1964-08-15 | R40: 24 | T40: 101 | U40: {=_xlfn.TEXTJOIN(",",TRUE,_xlfn.XLOOKUP(_xlfn.FILTERXML("<t><s>" & SUBSTITUTE(T40,",","</s><s>") & "</s></t>", "//s"),Writers!$A$3:$A$999,Writers!$B$3:$B$999,""))} -> Dennis Spooner | W40: =IF(V40="","",_xlfn.XLOOKUP(V40,Writers!$A$3:$A$999,Writers!$B$3:$B$999,"")) | X40: 6.9 | AA40: =IF(ISBLANK(X40),"",ROUND(X40*AE40,2)) -> 8.73 | AB40: =IF(ISBLANK(Y40),"",ROUND(Y40*AE40,2)) | AC40: =IF(ISBLANK(Z40),"",ROUND(Z40*AE40,2)) | AD40: =VLOOKUP(YEAR(Q40),Populations!$A$3:$B$999,2,0) -> 53990800 | AE40: =(Calculations!B1/AD40) -> 1.2651217 | AG40: 1 | AH40: =VLOOKUP(AG40,WikiFormats!$A$3:$B$999,2,0) -> Story | AI40: https://en.wikipedia.org/wiki/The_Reign_of_Terror_(Doctor_Who)
A41: 39 | B41: 1 | C41: =VLOOKUP(B41,Eras!$A$3:$B$999,2,0) -> Classic | D41: 1 | E41: =VLOOKUP(D41,EpisodeFormats!$A$3:$B$999,2,0) -> Series | F41: 1 | G41: =VLOOKUP(F41,Doctors!$A$3:$B$999,2,0) -> William Hartnell | H41: 1 | I41: 1 | J41: =VLOOKUP(I41,SeasonFormats!$A$3:$B$999,2,0) -> Season | K41: 8 | L41: 8 | M41: The Reign of Terror | N41: 3 | O41: A Change of Identity | P41: 39 | Q41: 1964-08-22 | R41: 25 | T41: 101 | U41: {=_xlfn.TEXTJOIN(",",TRUE,_xlfn.XLOOKUP(_xlfn.FILTERXML("<t><s>" & SUBSTITUTE(T41,",","</s><s>") & "</s></t>", "//s"),Writers!$A$3:$A$999,Writers!$B$3:$B$999,""))} -> Dennis Spooner | W41: =IF(V41="","",_xlfn.XLOOKUP(V41,Writers!$A$3:$A$999,Writers!$B$3:$B$999,"")) | X41: 6.9 | AA41: =IF(ISBLANK(X41),"",ROUND(X41*AE41,2)) -> 8.73 | AB41: =IF(ISBLANK(Y41),"",ROUND(Y41*AE41,2)) | AC41: =IF(ISBLANK(Z41),"",ROUND(Z41*AE41,2)) | AD41: =VLOOKUP(YEAR(Q41),Populations!$A$3:$B$999,2,0) -> 53990800 | AE41: =(Calculations!B1/AD41) -> 1.2651217 | AG41: 1 | AH41: =VLOOKUP(AG41,WikiFormats!$A$3:$B$999,2,0) -> Story | AI41: https://en.wikipedia.org/wiki/The_Reign_of_Terror_(Doctor_Who)
...

Sheet Doctors
A1: Number | B1: Actor
A3: 1 | B3: William Hartnell
A4: 2 | B4: Patrick Troughton
A5: 3 | B5: Jon Pertwee
A6: 4 | B6: Tom Baker
A7: 5 | B7: Peter Davison
A8: 6 | B8: Colin Baker
A9: 7 | B9: Sylvester McCoy
A10: 8 | B10: Paul McGann
A11: 9 | B11: Christopher Eccleston
A12: 10 | B12: David Tennant
A13: 11 | B13: Matt Smith
A14: 12 | B14: Peter Capaldi
... A17: 15 | B17: Ncuti Gatwa

Sheet SeasonFormats
A1: Id | B1: Description
A3: 1 | B3: Season
A4: 2 | B4: Movie
A5: 3 | B5: Series
A6: 4 | B6: Special

Sheet EpisodeFormats
A1: Id | B1: Description
A3: 1 | B3: Series
A4: 2 | B4: Special
A5: 3 | B5: Movie

Sheet Eras
A1: Id | B1: Description
A3: 1 | B3: Classic
A4: 2 | B4: Movie/Universal
A5: 3 | B5: New
A6: 4 | B6: New/Disney

Sheet Writers
A1: Id | B1: Name | C1: IsAlias | D1: Note
A3: 1 | B3: Ben Aaronovitch
A4: 2 | B4: Douglas Adams
A5: 3 | B5: David Agnew | C5: 1 | D5: (Graham Williams and Anthony Read), (Douglas Adams and Graham Williams, from a story by David Fisher)
A6: 4 | B6: Maxine Alderton
A7: 5 | B7: Sharma Angel-Walfall
A8: 6 | B8: Norman Ashby | C8: 1 | D8: (Mervyn Haisman and Henry Lincoln)
A9: 7 | B9: Christopher Bailey
A10: 8 | B10: Bob Baker
A11: 9 | B11: Pip and Jane Baker
A12: 10 | B12: Mike Bartlett
A13: 11 | B13: Christopher H. Bidmead
A14: 12 | B14: Ian Stuart Black
A15: 13 | B15: Malorie Blackman
A16: 14 | B16: Robin Bland | C16: 1 | D16: (Terrance Dicks and Robert Holmes)
A17: 15 | B17: Chris Boucher
A18: 16 | B18: Ian Briggs
A19: 17 | B19: Johnny Byrne
A20: 18 | B20: Chris Chibnall
A21: 19 | B21: Kevin Clarke
A22: 20 | B22: Barbara Clegg
A23: 21 | B23: Anthony Coburn
A24: 22 | B24: Paul Cornell
A25: 23 | B25: Donald Cotton
A26: 24 | B26: Frank Cottrell-Boyce
A27: 25 | B27: Neil Cross
A28: 26 | B28: Graeme Curry
... A51: 49 | B51: Peter Harness
A52: 50 | B52: Stephen Harris | C52: 1 | D52: (Lewis Greifer and Robert Holmes)
A53: 51 | B53: Brian Hayles
A54: 52 | B54: Kate Herron
A55: 53 | B55: Ed Hime
A56: 54 | B56: Robert Holmes
A57: 55 | B57: Don Houghton
A58: 56 | B58: Malcolm Hulke
A59: 57 | B59: Matthew Jacobs
A60: 58 | B60: Charlene James
A61: 59 | B61: Elwyn Jones
A62: 60 | B62: Glyn Jones
A63: 61 | B63: Matt Jones
...

Sheet WikiFormats
A1: Id | B1: Description
A3: 1 | B3: Story
A4: 2 | B4: Episode

Sheet Populations
A1: Year | B1: Population | C1: Note
A3: 1963 | B3: 53624900
A4: 1964 | B4: 53990800
A5: 1965 | B5: 54349500
A6: 1966 | B6: 54642700
A7: 1967 | B7: 54959000
A8: 1968 | B8: 55213500
A9: 1969 | B9: 55460600
A10: 1970 | B10: 55632200
A11: 1971 | B11: 55928000
A12: 1972 | B12: 56096700
A13: 1973 | B13: 56222900
A14: 1974 | B14: 56235600
... A60: 2020 | B60: 67081200
A61: 2021 | B61: 67350695 | C61: Projection only
A62: 2022 | B62: 67595824 | C62: Projection only
A63: 2023 | B63: 67844315 | C63: Projection only
A64: 2024 | B64: 68081792 | C64: Projection only
A65: 2025 | B65: 68304932 | C65: Projection only

Sheet Calculations
A1: CurrentPopulation | B1: {=LOOKUP(2,1/(NOT(ISBLANK(Populations!B:B))),Populations!B:B)} -> 68304932
